Workbook

Sheet Centralizator facultate
A2: Facultate: | B2: Științe Agricole, Industrie Alimentară și Protecția Medului
D3: Cd doc Prof Conf Lect/Șl Asist | E3: Cd doc: 500 Prof: 350 Conf: 300 Lect/Șl: 250 Asistent 200 | K3: Atentie! Plafon maxim! | L3: Atentie! Plafon maxim! | M3: Atentie! Plafon maxim! | P3: Atentie! Plafon maxim! | Q3: Atentie! Plafon maxim! | R3: Atentie! Plafon maxim! | S3: Atentie! Plafon maxim! | T3: Atentie! Plafon maxim! | U3: Atentie! Plafon maxim! | X3: Atentie! Plafon maxim! | Y3: Atentie! Plafon maxim! | AC3: Galben = OK Rosu = ATENTIE | AD3: Galben = OK Rosu = ATENTIE
A4: Nr. crt. | B4: Numele și prenumele | C4: Cod Departament | D4: Grad didactic la 01.01.2019 | E4: Punctaj de referinta cf grad didactic | F4: I1 | G4: I2 | H4: I3 | I4: I4 | J4: I5 | K4: I6 | L4: I7 | M4: I8 | N4: I9 | O4: I10 | P4: I11 | Q4: I12 | R4: I13 | S4: I14 | T4: I15 | U4: I16 | V4: I17 | W4: I18 | X4: I19 | Y4: I20 | Z4: TOTAL | AA4: Punctaj centralizator individual semnat | AB4: Punctaj centralizator facultate | AC4: Diferente TOTAL - Centralizator individual | AD4: Diferente TOTAL - Centralizator facultate
A5: 1 | B5: ANTOFIE Maria Mihaela | C5: FSAA2 | D5: Conferenţiar | E5: 300 | G5: 250 | H5: 400 | K5: 240 | L5: 48 | N5: 166.46 | S5: 200 | T5: 100 | Y5: 30 | Z5: =SUM(F5:Y5) -> 1434.46 | AA5: 1434.46 | AB5: 1434.46 | AC5: =Z5-AA5 -> 0 | AD5: =Z5-AB5 -> 0
A6: 2 | B6: ANTONIE Iuliana | C6: FSAA2 | D6: Şef lucrări | E6: 250 | H6: 200 | N6: 105.89 | U6: 50 | Y6: 40 | Z6: =SUM(F6:Y6) -> 395.89 | AA6: 395.89 | AB6: 395.89 | AC6: =Z6-AA6 -> 0 | AD6: =Z6-AB6 -> 0
A7: 3 | B7: BARBU Constantin Horia | C7: FSAA2 | D7: Profesor | E7: 350 | N7: 332.32 | Y7: 20 | Z7: =SUM(F7:Y7) -> 352.32 | AA7: 352.32 | AB7: 352.32 | AC7: =Z7-AA7 -> 0 | AD7: =Z7-AB7 -> 0
A8: 4 | B8: BARBU Ion | C8: FSAA2 | D8: Şef lucrări | E8: 250 | N8: 12.5 | Z8: =SUM(F8:Y8) -> 12.5 | AA8: 12.5 | AB8: 12.5 | AC8: =Z8-AA8 -> 0 | AD8: =Z8-AB8 -> 0
A9: 5 | B9: BLAJ Robert | C9: FSAA2 | D9: Conferenţiar | E9: 300 | H9: 300 | N9: 152.14 | Y9: 20 | Z9: =SUM(F9:Y9) -> 472.14 | AA9: 472.14 | AB9: 472.14 | AC9: =Z9-AA9 -> 0 | AD9: =Z9-AB9 -> 0
A10: 6 | B10: BRATU Iulian Alexandru | C10: FSAA2 | D10: Şef lucrări | E10: 250 | I10: 50 | J10: 70 | L10: 300 | N10: 73.75 | Y10: 20 | Z10: =SUM(F10:Y10) -> 513.75 | AA10: 513.75 | AB10: 513.75 | AC10: =Z10-AA10 -> 0 | AD10: =Z10-AB10 -> 0
A11: 7 | B11: CĂPĂŢÂNĂ Ciprian | C11: FSAA2 | D11: Ş.l. | E11: 250 | L11: 270 | Z11: =SUM(F11:Y11) -> 270 | AA11: 270 | AB11: 270 | AC11: =Z11-AA11 -> 0 | AD11: =Z11-AB11 -> 0
A12: 8 | B12: CĂRĂTUŞ Mirela Aurora | C12: FSAA2 | D12: Conferenţiar | E12: 300 | H12: 707 | N12: 276.5 | Y12: 20 | Z12: =SUM(F12:Y12) -> 1003.5 | AA12: 1003.5 | AB12: 1003.5 | AC12: =Z12-AA12 -> 0 | AD12: =Z12-AB12 -> 0
A13: 9 | B13: CREŢU Carmen Monica | C13: FSAA2 | D13: Conf. | E13: 300 | L13: 200 | N13: 38.34 | T13: 100 | Y13: 20 | Z13: =SUM(F13:Y13) -> 358.34 | AA13: 358.34 | AB13: 358.34 | AC13: =Z13-AA13 -> 0 | AD13: =Z13-AB13 -> 0
A14: 10 | B14: CRISTEA Ramona | C14: FSAA2 | D14: Ș.l. | E14: 250 | N14: 48.32 | Y14: 40 | Z14: =SUM(F14:Y14) -> 88.32 | AA14: 88.32 | AB14: 88.32 | AC14: =Z14-AA14 -> 0 | AD14: =Z14-AB14 -> 0
A15: 11 | B15: DANCIU Cristina Anca | C15: FSAA2 | D15: Ş.l. | E15: 250 | L15: 300 | Z15: =SUM(F15:Y15) -> 300 | AA15: 300 | AB15: 300 | AC15: =Z15-AA15 -> 0 | AD15: =Z15-AB15 -> 0
A16: 12 | B16: DRĂGHICI Olga | C16: FSAA2 | D16: Ş.l. | E16: 250 | G16: 291.67 | L16: 300 | N16: 187.5 | O16: 33.33 | T16: 75 | Z16: =SUM(F16:Y16) -> 887.5 | AA16: 887.5 | AB16: 887.5 | AC16: =Z16-AA16 -> 0 | AD16: =Z16-AB16 -> 0
A17: 13 | B17: DUMITRU Mariana Lenuţa | C17: FSAA2 | D17: Conferenţiar | E17: 300 | H17: 200 | Z17: =SUM(F17:Y17) -> 200 | AA17: 200 | AB17: 200 | AC17: =Z17-AA17 -> 0 | AD17: =Z17-AB17 -> 0
A18: 14 | B18: GASPAR Eniko | C18: FSAA2 | D18: Şef lucrări | E18: 250 | Y18: 20 | Z18: =SUM(F18:Y18) -> 20 | AA18: 20 | AB18: 20 | AC18: =Z18-AA18 -> 0 | AD18: =Z18-AB18 -> 0
A19: 15 | B19: GEORGESCU Cecilia | C19: FSAA2 | D19: Conf. | E19: 300 | F19: 562.5 | H19: 100 | J19: 8.75 | N19: 1004.39 | S19: 150 | T19: 200 | U19: 50 | Y19: 48 | Z19: =SUM(F19:Y19) -> 2123.64 | AA19: 2123.64 | AB19: 2123.64 | AC19: =Z19-AA19 -> 0 | AD19: =Z19-AB19 -> 0
A20: 16 | B20: IAGĂRU Pompilica | C20: FSAA2 | D20: Şef lucrări | E20: 250 | G20: 125 | H20: 40 | N20: 61.25 | T20: 75 | Y20: 20 | Z20: =SUM(F20:Y20) -> 321.25 | AA20: 321.25 | AB20: 321.25 | AC20: =Z20-AA20 -> 0 | AD20: =Z20-AB20 -> 0
A21: 17 | B21: IAGĂRU Romulus | C21: FSAA2 | D21: Profesor | E21: 350 | G21: 125 | H21: 40 | J21: 35 | N21: 57.5 | S21: 50 | T21: 125 | Y21: 20 | Z21: =SUM(F21:Y21) -> 452.5 | AA21: 452.5 | AB21: 452.5 | AC21: =Z21-AA21 -> 0 | AD21: =Z21-AB21 -> 0
A22: 18 | B22: IANCU Maria Lidia | C22: FSAA2 | D22: Ş.l. | E22: 250 | H22: 200 | L22: 300 | N22: 362.5 | T22: 25 | Y22: 20 | Z22: =SUM(F22:Y22) -> 907.5 | AA22: 907.5 | AB22: 907.5 | AC22: =Z22-AA22 -> 0 | AD22: =Z22-AB22 -> 0
A23: 19 | B23: KETNEY Otto | C23: FSAA2 | D23: Ş.l. | E23: 250 | N23: 630.43 | T23: 200 | Y23: 10 | Z23: =SUM(F23:Y23) -> 840.43 | AA23: 840.43 | AB23: 840.43 | AC23: =Z23-AA23 -> 0 | AD23: =Z23-AB23 -> 0
A24: 20 | B24: LENGYEL Ecaterina | C24: FSAA2 | D24: Ş.l. | E24: 250 | H24: 50 | J24: 14 | N24: 399.32 | Y24: 40 | Z24: =SUM(F24:Y24) -> 503.32 | AA24: 503.32 | AB24: 503.32 | AC24: =Z24-AA24 -> 0 | AD24: =Z24-AB24 -> 0
A25: 21 | B25: MIRONESCU Ion Dan | C25: FSAA2 | D25: Conf. | E25: 300 | K25: 37.5 | N25: 57.5 | T25: 200 | W25: 100 | Y25: 20 | Z25: =SUM(F25:Y25) -> 415 | AA25: 415 | AB25: 415 | AC25: =Z25-AA25 -> 0 | AD25: =Z25-AB25 -> 0
A26: 22 | B26: MIRONESCU Monica | C26: FSAA2 | D26: Conf. | E26: 300 | J26: 8.75 | N26: 545.51 | S26: 200 | T26: 200 | V26: 110 | W26: 400 | Y26: 58 | Z26: =SUM(F26:Y26) -> 1522.26 | AA26: 1522.26 | AB26: 1522.26 | AC26: =Z26-AA26 -> 0 | AD26: =Z26-AB26 -> 0
A27: 23 | B27: MOISE George | C27: FSAA2 | D27: Ş.l. | E27: 250 | H27: 200 | N27: 250 | U27: 50 | Y27: 40 | Z27: =SUM(F27:Y27) -> 540 | AA27: 540 | AB27: 540 | AC27: =Z27-AA27 -> 0 | AD27: =Z27-AB27 -> 0
A28: 24 | B28: MOISE Maria Cristina | C28: FSAA2 | D28: Şef lucrări | E28: 250 | H28: 725 | N28: 215 | U28: 50 | Y28: 40 | Z28: =SUM(F28:Y28) -> 1030 | AA28: 1030 | AB28: 1030 | AC28: =Z28-AA28 -> 0 | AD28: =Z28-AB28 -> 0
A29: 25 | B29: OANCEA Simona Rodica | C29: FSAA2 | D29: Prof. | E29: 500 | G29: 725 | H29: 418.18 | N29: 1622.57 | O29: 33.33 | S29: 100 | W29: 300 | Z29: =SUM(F29:Y29) -> 3199.08 | AA29: 3199.08 | AB29: 3199.08 | AC29: =Z29-AA29 -> 0 | AD29: =Z29-AB29 -> 0
A30: 26 | B30: OGNEAN Claudia Felicia | C30: FSAA2 | D30: Ş.l. | E30: 250 | N30: 176.67 | T30: 25 | Y30: 40 | Z30: =SUM(F30:Y30) -> 241.67 | AA30: 241.67 | AB30: 241.67 | AC30: =Z30-AA30 -> 0 | AD30: =Z30-AB30 -> 0
A31: 27 | B31: OGNEAN Mihai | C31: FSAA2 | D31: Ş.l. | E31: 250 | N31: 176.67 | T31: 50 | W31: 63.5 | Y31: 40 | Z31: =SUM(F31:Y31) -> 330.17 | AA31: 330.17 | AB31: 330.17 | AC31: =Z31-AA31 -> 0 | AD31: =Z31-AB31 -> 0
A32: 28 | B32: PĂCALĂ Mariana Liliana | C32: FSAA2 | D32: Ş.l. | E32: 250 | L32: 155 | N32: 51.66 | T32: 50 | Z32: =SUM(F32:Y32) -> 256.66 | AA32: 256.66 | AB32: 256.66 | AC32: =Z32-AA32 -> 0 | AD32: =Z32-AB32 -> 0
A33: 29 | B33: PĂŞCĂNUŢ Ioan | C33: FSAA2 | D33: Şef lucrări | E33: 250 | Y33: 20 | Z33: =SUM(F33:Y33) -> 20 | AA33: 20 | AB33: 20 | AC33: =Z33-AA33 -> 0 | AD33: =Z33-AB33 -> 0
A34: 30 | B34: POP Mihai Radu | C34: FSAA2 | D34: Şef lucrări | E34: 250 | N34: 21.37 | Y34: 20 | Z34: =SUM(F34:Y34) -> 41.37 | AA34: 41.37 | AB34: 41.37 | AC34: =Z34-AA34 -> 0 | AD34: =Z34-AB34 -> 0
A35: 31 | B35: ŞANDRU Daniela Maria | C35: FSAA2 | D35: Asist. | E35: 200 | J35: 140 | N35: 28.75 | Y35: 20 | Z35: =SUM(F35:Y35) -> 188.75 | AA35: 188.75 | AB35: 188.75 | AC35: =Z35-AA35 -> 0 | AD35: =Z35-AB35 -> 0
A36: 32 | B36: SAVA Camelia | C36: FSAA2 | D36: Profesor | E36: 350 | H36: 200 | L36: 170 | M36: 50 | N36: 140.47 | S36: 200 | T36: 125 | U36: 10 | Y36: 30 | Z36: =SUM(F36:Y36) -> 925.47 | AA36: 925.47 | AB36: 925.47 | AC36: =Z36-AA36 -> 0 | AD36: =Z36-AB36 -> 0
A37: 33 | B37: SAVATIE Mircea Benvenuto | C37: FSAA2 | D37: Şef lucrări | E37: 250 | Y37: 20 | Z37: =SUM(F37:Y37) -> 20 | AA37: 20 | AB37: 20 | AC37: =Z37-AA37 -> 0 | AD37: =Z37-AB37 -> 0
A38: 34 | B38: SIMTION Daniela Maria | C38: FSAA2 | D38: Şef lucrări | E38: 250 | H38: 400 | N38: 130 | Z38: =SUM(F38:Y38) -> 530 | AA38: 530 | AB38: 530 | AC38: =Z38-AA38 -> 0 | AD38: =Z38-AB38 -> 0
A39: 35 | B39: ŞIPOŞ Anca Sorina | C39: FSAA2 | D39: Prof. | E39: 350 | F39: 2333.33 | I39: 25 | L39: 290 | N39: 100 | T39: 75 | Z39: =SUM(F39:Y39) -> 2823.33 | AA39: 2823.33 | AB39: 2823.33 | AC39: =Z39-AA39 -> 0 | AD39: =Z39-AB39 -> 0
A40: 36 | B40: SPÂNU Simona Mariana | C40: FSAA2 | D40: Şef lucrări | E40: 250 | I40: 50 | K40: 15.75 | L40: 9 | N40: 142.5 | T40: 200 | Y40: 20 | Z40: =SUM(F40:Y40) -> 437.25 | AA40: 437.25 | AB40: 437.25 | AC40: =Z40-AA40 -> 0 | AD40: =Z40-AB40 -> 0
A41: 37 | B41: TIŢA Mihaela Adriana | C41: FSAA2 | D41: Prof. | E41: 350 | F41: 375 | H41: 300 | J41: 315 | K41: 378 | N41: 98.75 | S41: 150 | T41: 200 | Y41: 60 | Z41: =SUM(F41:Y41) -> 1876.75 | AA41: 1876.75 | AB41: 1876.75 | AC41: =Z41-AA41 -> 0 | AD41: =Z41-AB41 -> 0
...

Sheet I.1
A2: I.1 - Articol în revistă WoS: SCIS, SSCI situată în ”zona rosie” / Q1, ”zona galbenă” / Q2, respectiv AHCI > 5 ani
A4: Articole încadrate “document type” ca “Article” sau „Review” în reviste cotate WoS (Web of Science) - SCIE - Science Citation Index Expanded şi SSCI - Social Sciences Citation Index), din ”zona roşie”/Q1, şi ”zona galbenă”/Q2 în conformitate cu Listele UEFISCDI a revistelor încadrate pe subdomenii ştiinţifice, respectiv în reviste AHCI - Arts & Humanities Citation Index cu o vechime de cel puţin 5 ani în Web of Science Core Collection, în conformitate cu Lista UEFISCDI a revistelor indexate in AHCI.
A5: Articolul trebuie publicat în anul de raportare şi să fie vizibil în Web of Science Core Collection din platforma www.webofknowledge.com
A6: Listele de referință UEFISCDI sunt cele din anul anterior raportării și sunt disponibile pe site-ul https://uefiscdi.ro/scientometrie-reviste. În cazul în care o revistă este încadrată în mai multe subdomenii, se ia în calcul încadrarea cea mai favorabilă.
A7: Articolul trebuie să conţină menţiunea afilierii la ULBS a declarantului.
A8: * Punctaje de referință: • Articol în zona roşie / Q1 = 1500 de puncte • Articol in zona galbenă / Q2 = 1000 de puncte • Articol in AHCI > 5 ani: 1200 puncte Punctajul se împarte la numărul de autori cu afiliere la instituţiile de învăţământ şi cercetare din România, inclusiv la doctoranzi / studenţi. Punctajul NU se împarte cu autorii din străinătate sau cu autorii din mediul de afaceri (pentru acești autori se menţionează în paranteză instituţia de proveniență).
A10: Titlul articolului | B10: Numele și prenumele autorilor (afilierea) | C10: Cod departament | D10: Titlul revistei | E10: Volum | F10: Număr | G10: ISSN revistă | H10: Link către articol pe site - ul revistei | I10: DOI articol (Digital object identifier) | J10: WOS Accession Number | K10: Paginile articolului (de la … până la …) | L10: Anul publicării | M10: Tipul revistei (zona rosie/Q1; zona galbena/Q2; AHCI>5ani) | N10: Factor de impact revistă | O10: Punctaj de referință* | P10: Punctaj individual | Q10: Numele și prenumele Declarant
A11: Bilberry (Vaccinium myrtillus L.) Extracts Comparative Analysis Regarding Their Phytonutrient Profiles, Antioxidant Capacity along with the In Vivo Rescue Effects Tested on a Drosophila melanogaster High-Sugar Diet Model | B11: Andreea-Adriana Neamtu-University of Oradea, Rita Szoke-Kovacs, Emoke Mihok, University of Debrecen, Cecilia Georgescu, “Lucian Blaga” University of Sibiu, Violeta Turcus, Neli Kinga Olah, “Vasile Goldis” Western University of Arad, Adina Frum, Ovidiu Tita, “Lucian Blaga” University of Sibiu, Carmen Neamtu, “Vasile Goldis” Western University of Arad, Zsombor Szoke-Kovacs, University of Debrecen, Zoltan Cziaky, Agricultural and Molecular Research and Service Institute, University of Nyiregyhaza and Endre Mathe, University of Debrecen and “Vasile Goldis” Western University of Arad | C11: FSAA2 | D11: Antioxidants | E11: 9 | F11: 11 | G11: ISSN: eISSN: 2076-3921 | H11: Antioxidants | Free Full-Text | Bilberry (Vaccinium myrtillus L.) Extracts Comparative Analysis Regarding Their Phytonutrient Profiles, Antioxidant Capacity along with the In Vivo Rescue Effects Tested on a Drosophila melanogaster High-Sugar Diet Model (mdpi.com) | I11: doi:10.3390/antiox9111067 | J11: WOS:000592780600001 | K11: 1-33 | L11: 2020 | M11: Q1 | N11: 5.014 | O11: 1500 | P11: 187.5 | Q11: Georgescu Cecilia
A12: Use of Yoghurt Enhanced with Volatile Plant Oils Encapsulated in Sodium Alginate to Increase the Human Body's Immunity in the Present Fight Against Stress | B12: Tita Ovidiu, Constantinescu Maria Adelina, Tita Mihaela Adriana, Georgescu Cecilia, “Lucian Blaga” University of Sibiu | C12: FSAA2 | D12: INTERNATIONAL JOURNAL OF ENVIRONMENTAL RESEARCH AND PUBLIC HEALTH | E12: 17 | F12: 20 | G12: ISSN: eISSN: 1660-4601 | H12: https://www.mdpi.com/1660-4601/17/20/7588 | I12: 10.3390/ijerph17207588 | J12: WOS:000585597700001 | K12: 1-17 | L12: 2020 | M12: Q1 | N12: 2.849 | O12: 1500 | P12: 375 | Q12: Georgescu Cecilia
A13: Sustainable Method Using Filtering Techniques for a Fermentation Process State Estimation | B13: Anca Sipos | C13: FSAA2 | D13: Sustainability | E13: 12 | F13: 17 | G13: 2071-1050 | H13: https://www.mdpi.com/2071-1050/12/17/7105 | I13: https://doi.org/10.3390/su12177105 | J13: WOS:000570331900001 | K13: 7105-7119 | L13: 44074 | M13: Q2 | N13: 2.576 | O13: 1000 | P13: 1000 | Q13: Sipos Anca
A14: A Knowledge-Based System as a Sustainable Software Application for the Supervision and Intelligent Control of an Alcoholic Fermentation Process | B14: Anca Sipos | C14: FSAA2 | D14: Sustainability | E14: 12 | F14: 23 | G14: 2071-1050 | H14: https://www.mdpi.com/2071-1050/12/23/10205 | I14: https://doi.org/10.3390/su122310205 | J14: WOS:000597489300001 | K14: 10205-10221 | L14: 7 Decembrie 2020 | M14: Q2 | N14: 2.576 | O14: 1000 | P14: 1000 | Q14: Sipos Anca
A15: Using Neural Networks to Obtain Indirect Information about the State Variables in an Alcoholic Fermentation Process | B15: Anca Sipos, Adrian Florea, Maria Arsin and Ugo Fiore | C15: FSAA2 | D15: Processes | E15: 9 | F15: 1 | H15: https://www.mdpi.com/2227-9717/9/1/74 | I15: https://doi.org/10.3390/pr9010074 | J15: WOS:000610732300001 | K15: 74-92 | L15: 31 Decembrie 2020 | M15: Q2 | N15: 2.753 | O15: 1000 | P15: 333.33 | Q15: Sipos Anca
A16: Use of Yoghurt Enhanced with Volatile Plant Oils Encapsulated in Sodium Alginate to Increase the Human Body’s Immunity in the Present Fight Against Stres | B16: Ovidiu Tita, Maria Adelina Constantinescu, Mihaela Adriana Tita, Cecilia Georgescu-ULBS | C16: FSAA2 | D16: Int. J. Environ. Res. Public Health | E16: 17 | F16: 20 | G16: 1660-4601 | H16: https://www.mdpi.com/1660-4601/17/20/7588 | I16: doi:10.3390/ijerph17207588, | J16: WOS:000585597700001 | K16: 1-17 | L16: 2020 | M16: Q1 | N16: 2849 | O16: 1500 | P16: 375 | Q16: Tita Mihaela
A17: Bilberry (Vaccinium myrtillus L.) Extracts Comparative Analysis Regarding Their Phytonutrient Profiles, Antioxidant Capacity along with the In Vivo Rescue Effects Tested on a Drosophila melanogaster High-Sugar Diet Model | B17: Andreea-Adriana Neamtu -University of Oradea, Romania; Rita Szoke-Kovacs - University of Debrecen, Hungary; Emoke Mihok - University of Debrecen, Hungary; Cecilia Georgescu - “Lucian Blaga” University of Sibiu, Romania; Violeta Turcus - “Vasile Goldis” Western University of Arad, Romania; Neli Kinga Olah - Faculty of Pharmacy, “Vasile Goldis” Western University of Arad, Romania; Adina Frum - “Lucian Blaga” University of Sibiu, Romania; Ovidiu Tita - “Lucian Blaga” University of Sibiu, Romania; Carmen Neamtu - “Vasile Goldis” Western University of Arad, Romania; Zsombor Szoke-Kovacs - University of Debrecen, Hungary; Zoltan Cziaky - University of Nyiregyhaza, Hungary; Endre Mathe -University of Debrecen, Hungary | C17: FSAA2 | D17: Antioxidants | E17: 9 | F17: 11 | G17: (ISSN 2076-3921 | H17: https://www.mdpi.com/2076-3921/9/11/1067 | I17: https://doi.org/10.3390/antiox9111067 | J17: WOS:000592780600001 | K17: 1-33 | L17: 2020 | M17: Q1 | N17: 5.014 | O17: 1500 | P17: 187.5 | Q17: Tita Ovidiu
A18: Use of Yoghurt Enhanced with Volatile Plant Oils Encapsulated in Sodium Alginate to Increase the Human Body’s Immunity in the Present Fight Against Stress | B18: Ovidiu Tița- “Lucian Blaga” University of Sibiu, 550012 Sibiu, Romania; Maria Adelina Constantinescu - “Lucian Blaga” University of Sibiu, 550012 Sibiu, Romania; Mihaela Adriana Tița - “Lucian Blaga” University of Sibiu, 550012 Sibiu, Romania;Cecilia Georgescu - “Lucian Blaga” University of Sibiu, 550012 Sibiu, Romania; | C18: FSAA2 | D18: International Journal of Environmental Research and Public Health | E18: 17 | F18: 20 | H18: https://www.mdpi.com/1660-4601/17/20/7588 | I18: https://doi.org/10.3390/ijerph17207588 | J18: WOS:000585597700001 | L18: 2020 | M18: Q1 | N18: 2.849 | O18: 1500 | P18: 375 | Q18: Tita Ovidiu
A61: TOTAL | P61: =SUM(P11:P60) -> 3833.33
A63: Informațiile incomplete / incorecte vor conduce la neluarea în calcul a indicatorului respectiv

Sheet I.2
A2: I.2- Articol în revistă cotată WoS: SCIS, SSCI – „zona gri”/ Q3, Q4 şi respectiv AHCI < 5 ani, conform listelor UEFISCDI
A4: Articole încadrate “document type” ca “Article” sau „Review” în reviste cotate WoS TR - Web of Science Thomson Reuters (SCIE - Science Citation Index Expanded şi SSCI - Social Sciences Citation Index, din ”zona gri”/ Q3, Q4, în conformitate cu Lista UEFISCDI a revistelor încadrate pe subdomenii ştiinţifice, respectiv în reviste AHCI - Arts & Humanities Citation Index cu o vechime mai mică de 5 ani în Web of Science Core Collection.
A5: Articolul trebuie publicat în anul de raportare şi să fie vizibil în Web of Science Core Collection din platforma www.webofknowledge.com
A6: Listele de referință UEFISCDI sunt cele din anul anterior raportării și sunt disponibile pe site-ul https://uefiscdi.ro/scientometrie-reviste. În cazul în care o revistă este încadrată în mai multe subdomenii, se ia în calcul încadrarea cea mai favorabilă.
A7: Articolul trebuie să conţină menţiunea afilierii la ULBS a declarantului.
A8: * Punctaje de referință: • Articol = 500 de puncte Punctajul se împarte la numărul de autori cu afiliere la instituţiile de învăţământ şi cercetare din România, inclusiv la doctoranzi / studenţi. Punctajul NU se împarte cu autorii din străinătate sau cu autorii din mediul de afaceri (pentru acești autori se menţionează în paranteză instituţia de proveniență).
A10: Titlul articolului | B10: Numele și prenumele autorilor (afilierea) | C10: Cod departament | D10: Titlul revistei | E10: Volum | F10: Număr | G10: ISSN revistă | H10: Link către articol pe site - ul revistei | I10: DOI articol (Digital object identifier) | J10: WOS Accession Number | K10: Paginile articolului (de la … până la …) | L10: Anul publicării | M10: Tipul revistei zona gri /Q3, Q4; AHCI<5ani) | N10: Factor de impact | O10: Punctaj de referință* | P10: Punctaj individual | Q10: Numele și prenumele Declarant
A11: Lovastatin effects on indirect somatic embryogenesis of petunia | B11: Antofie MM (ULBS) Mitoi ME (IBB) | C11: FSAA2 | D11: ROMANIAN BIOTECHNOLOGICAL LETTERS | E11: 25 | F11: 5 | G11: 1224-5984 | H11: https://www.e-repository.org/rbl/vol.25/iss.5/4.pdf | I11: 10.25083/rbl/25.5/1886.1891 | J11: WOS:000571493000004 | K11: 1886-1891 | L11: 2020 | M11: Q4 | N11: 0.765 | O11: 500 | P11: =O11/2 -> 250 | Q11: Antofie Mihaela
A12: AN ENZYME-ENHANCED EXTRACTION OF ANTHOCYANINS FROM RED CABBAGE AND THEIR THERMAL DEGRADATION KINETICS | B12: Tecucianu A-C, Drăghici O., Oancea S. | D12: Acta Alimentaria | E12: 49 | F12: 2 | G12: 0139-3006 | H12: https://akjournals.com/view/journals/066/49/2/article-p204.xml | I12: doi.org/10.1556/066.2020.49.2.10 | J12: WOS:000590169700010 | K12: 204–213 | L12: 2020 | M12: Q4 | N12: 0.547 | O12: 500 | P12: 166.67 | Q12: Draghici Olga
A13: Effects of roselle extract on the oxidative stability of hempseed oil | B13: Simona oancea – olga Drăghici – mirabela Perju – FranciSc V. DulF | D13: Journal of Food and Nutrition Research | E13: 59 | F13: 2 | G13: 1336-8672 | H13: http://www.vup.sk/en/download.php?bulID=2058 | J13: WOS:000541970600002 | K13: 98-107 | L13: 2020 | M13: Q4 | N13: 0.756 | O13: 500 | P13: =O13/4 -> 125 | Q13: Draghici Olga
A14: Sustainable resource management, the source of production integration, biodiversity conservation and socio-cultural values in grasway ecosystems. | B14: Iagăru, P. (ULB), Mărcuță, L. (USAMV), Iagăru, R. (ULB), & Mărcuță, A. (USAMV) | C14: FSAA2 | D14: ROMANIAN BIOTECHNOLOGICAL LETTERS, | E14: 25 | F14: (5), | G14: 1984-1991. | H14: https://www.rombio.org/vol.25/iss.5/publications.html | I14: 10.25083/rbl/25.5/1984.1991 | K14: 1984-1991 | L14: (2020). | M14: Q3 | N14: 0.823 | O14: 500 | P14: =O14/4 -> 125 | Q14: Iagaru Pompilica
A15: Sustainable resource management, the source of production integration, biodiversity conservation and socio-cultural values in grasway ecosystems. | B15: Iagăru, P. (ULB), Mărcuță, L. (USAMV), Iagăru, R. (ULB), & Mărcuță, A. (USAMV) | C15: FSAA2 | D15: ROMANIAN BIOTECHNOLOGICAL LETTERS, | E15: 25 | F15: (5), | G15: 1984-1991. | H15: https://www.rombio.org/vol.25/iss.5/publications.html | I15: 10.25083/rbl/25.5/1984.1991 | K15: 1984-1991 | L15: (2020). | M15: Q3 | N15: 0.823 | O15: 500 | P15: =O15/4 -> 125 | Q15: Iagaru Romulus
A16: Development of ultrasonic extracts with strong antioxidant properties from red onion wastes | B16: Oancea Simona, Radu M., Olosutean H. | C16: FSAA2 | D16: Rom. Biotech. Lett. | E16: 25 | F16: 2 | G16: 1224-5984 | H16: https://www.e-repository.org/rbl/vol.25/iss.2/2.pdf | I16: 10.25083/rbl/25.2/1320.1327 | J16: 539565000002 | K16: 1320-1327 | L16: 2020 | M16: Q4 | N16: 0.765 | O16: 500 | P16: =O16/3 -> 166.66667 | Q16: Oancea Simona
A17: Influence of enzyme-aided extraction and ultrasonication on phenolics content and antioxidant activity of Paeonia officinalis L. petals | B17: Oancea Simona, Perju M., Olosutean H. | C17: FSAA2 | D17: J. Serb. Chem. Soc. | E17: 85 | F17: 7 | G17: ISSN 0352-5139 (Print), ISSN 1820-7421 (Online) | H17: https://www.shd-pub.org.rs/index.php/JSCS/article/view/8545/950 | I17: 10.2298/JSC190807120O | J17: 550645700002 | K17: 845-856 | L17: 2020 | M17: Q4 | N17: 1.097 | O17: 500 | P17: =O17/3 -> 166.66667 | Q17: Oancea Simona
A18: Effects of roselle extract on the oxidative stability of hempseed oil | B18: Oancea Simona, Drăghici O., Perju M., Dulf F.V. | C18: FSAA2 | D18: J. Food Nutr. Res. | E18: 59 | F18: 2 | G18: 1336-8672. | H18: https://www.vup.sk/en/index.php?mainID=2&navID=34&version=2&volume=59&article=2180 | J18: 541970600002 | K18: 98-107 | L18: 2020 | M18: Q4 | N18: 0.756 | O18: 500 | P18: =O18/4 -> 125 | Q18: Oancea Simona
A19: An enzyme-enhanced extraction of anthocyanins from red cabbage and their thermal degradation kinetics | B19: Tecucianu A.C., Drăghici O., Oancea Simona | C19: FSAA2 | D19: Acta Alimentaria | E19: 49 | F19: 2 | G19: 0139-3006 | H19: https://akjournals.com/view/journals/066/49/2/article-p204.xml | I19: 10.1556/066.2020.49.2.10 | J19: 590169700010 | K19: 204-213 | L19: 2020 | M19: Q4 | N19: 0.458 | O19: 500 | P19: =O19/3 -> 166.66667 | Q19: Oancea Simona
A20: The impact of anthropogenic activities to the level of some POPs residues in bovine milk from several farms in Romania | B20: Stegarus D.I., Ionete R.E., Oancea Simona, Lengyel E., Frum A. | C20: FSAA2 | D20: Studia Universitatis Babes-Bolyai Chemia | E20: 65 | F20: 4 | G20: 1224-7154 | H20: http://chem.ubbcluj.ro/~studiachemia/issues/chemia2020_4/13Stegarus_159_176.pdf | I20: 10.24193/subbchem.2020.4.13 | J20: 601368800013 | K20: 159-176 | L20: 2020 | M20: Q4 | N20: 0.494 | O20: 500 | P20: =O20/5 -> 100 | Q20: Oancea Simona
A61: TOTAL | P61: =SUM(P11:P60) -> 1516.67
A63: Informațiile incomplete / incorecte vor conduce la neluarea în calcul a indicatorului respectiv

Sheet I.3
A2: I.3 - Articol în revistă din bazele de date Master Journal List (inclusiv Emerging Sources Citation Index - ESCI) şi articol în revistă indexată SCOPUS.
A4: Articole publicate în reviste din bazele de date: Master Journal List , inclusiv in Emerging Sources Citation Index (http://mjl.clarivate.com); SCOPUS (https://www.scopus.com/);
A5: Se consideră doar articole care au încadrarea “document type”: “article” sau “review”
A6: Articolul trebuie publicat în anul de raportare şi să fie vizibil pe platforma www.webofknowledge.com şi / sau pe platforma https://www.scopus.com/
A7: Articolul trebuie să conţină menţiunea afilierii la ULBS a declarantului.
A8: * Punctaje de referință: • Articol = 200 de puncte Punctajul se împarte la numărul de autori cu afiliere la instituţiile de învăţământ şi cercetare din România, inclusiv la doctoranzi / studenţi. Punctajul NU se împarte cu autorii din străinătate sau cu autorii din mediul de afaceri (pentru acești autori se menţionează în paranteză instituţia de proveniență).
A10: Titlul articolului | B10: Numele și prenumele autorilor (afilierea) | C10: Cod departament | D10: Titlul revistei | E10: Volum | F10: Număr | G10: ISSN-ul revistei | H10: Link către articol pe site - ul revistei | I10: DOI articol (Digital object identifier) | J10: WOS Accession Number | K10: Paginile articolului (de la … până la …) | L10: Anul publicării | M10: Punctaj de referință* | N10: Punctaj individual | O10: Numele și prenumele Declarant
A11: DEFINING INDICATORS FOR INVESTIGATING TRADITIONAL HOME-GARDENS IN ROMANIA | B11: Antofie MM (ULBS) | C11: FSAA2 | D11: SCIENTIFIC PAPERS-SERIES MANAGEMENT ECONOMIC ENGINEERING IN AGRICULTURE AND RURAL DEVELOPMENT | E11: 20 | F11: 4 | G11: 2284-7995 | H11: http://www.managementjournal.usamv.ro/pdf/vol.20_4/Art4.pdf | J11: WOS:000598213900004 | K11: 31-37 | L11: 2020 | M11: 200 | N11: 200 | O11: Antofie Mihaela
A12: INDICATORS FOR INVESTIGATING TRADITIONAL HOME-GARDENS IN ROMANIA - CROPS DIVERSITY IN MOSNA COMMUNE, SIBIU COUNTY | B12: Antofie MM, Sava C (ULBS) | C12: FSAA2 | D12: SCIENTIFIC PAPERS-SERIES MANAGEMENT ECONOMIC ENGINEERING IN AGRICULTURE AND RURAL DEVELOPMENT | E12: 20 | F12: 4 | G12: 2284-7995 | H12: http://managementjournal.usamv.ro/pdf/vol.20_4/Art5.pdf | J12: WOS:000598213900005 | K12: 39-47 | L12: 2020 | M12: 200 | N12: =M12/2 -> 100 | O12: Antofie Mihaela
A13: INDICATORS FOR INVESTIGATING TRADITIONAL HOME-GARDENS IN ROMANIA-VINEYRADS, FRUIT TREES AND CULTIVATED SHRUBS DIVERSITY IN MOȘNA COMMUNE, SIBIU COUNTY | B13: Antofie MM, Sava C (ULBS) | C13: FSAA2 | D13: SCIENTIFIC PAPERS-SERIES MANAGEMENT ECONOMIC ENGINEERING IN AGRICULTURE AND RURAL DEVELOPMENT | E13: 20 | F13: 4 | G13: 2284-7995 | H13: http://managementjournal.usamv.ro/pdf/vol.20_4/Art6.pdf | J13: WOS:000598213900006 | K13: 49-56 | L13: 200 | M13: 200 | N13: =M13/2 -> 100 | O13: Antofie Mihaela
A14: THE IMPORTANCE OF THE MELLIFEROUS FLORA FOR THE BEEKEEPING IN GURA RÂULUI COUNTRYSIDE AREA (SIBIU COUNTY), ROMANIA | B14: Antonie Iuliana | C14: FSAA2 | D14: SCIENTIFIC PAPERS-SERIES MANAGEMENT ECONOMIC ENGINEERING IN AGRICULTURE AND RURAL DEVELOPMENT | E14: 20 | F14: 4 | G14: 2284-7995 | H14: http://managementjournal.usamv.ro/pdf/vol.20_4/Art7.pdf | J14: WOS:000598213900007 | K14: 57-63 | L14: 2020 | M14: 200 | N14: 200 | O14: Antonie Iuliana
A15: Integrated control of damages and diseases within the forest ecosystem “miercurea sibiului” (Sibiu, romania) in the conditions of the year 2019 | B15: Stanca-Moise Cristina, Blaj R. | C15: FSAA | D15: Studia Universitatis Vasile Goldis Arad, Seria Stiintele Vietii | E15: 30 | F15: 3 | G15: ISSN: 15842363 | I15: https://www.scopus.com/record/display.uri?eid=2-s2.0-85097296954&origin=resultslist&sort=plf-f&src=s&st1=Stanc%c4%83+Moise&st2=Cristina&nlo=1&nlr=20&nls=count-f&sid=f45579bd40d782c3d8046c814a427337&sot=anl&sdt=aut&sl=43&s=AU-ID%28%22Stanc%c4%83-Moise%2c+Cristina%22+57191645933%29&relpos=0&citeCnt=0&searchTerm= | J15: Scopus | K15: 149-155 | L15: 2020 | M15: 200 | N15: 100 | O15: Blaj Robert
A16: NEW RESEARCH ON THE EVOLUTION OF Lymantria monacha L. (LEPIDOPTERA, LYMANTRIIDAE) IN THE CONDITIONS OF THE YEAR 2019 AND THE CONTROL OF THE PEST POPULATION WITHIN THE MIERCUREA SIBIULUI FOREST RANGE (ROMANIA) | B16: Cristina STANCĂ-MOISE, Robert BLAJ | C16: FSAA | D16: Muzeul Olteniei Craiova. Oltenia. Studii şi comunicări. Ştiinţele Naturii | E16: 36 | F16: 2 | G16: ISSN 1454-6914 | H16: http://olteniastudiisicomunicaristiintelenaturii.ro/v36_2.html | I16: http://olteniastudiisicomunicaristiintelenaturii.ro/cont/36_2/III.%20ANIMAL%20BIOLOGY%20III.a.%20INVERTEBRATES%20VARIOUS/12Moise.pdf | J16: ZOOR | K16: 84-90 | L16: 2020 | M16: 200 | N16: 100 | O16: Blaj Robert
A17: CONTROL OF THE Hylobius abietis L. (COLEOPTERA: CURCULIONIDAE) PEST DURING 2010-2019, WITHIN THE MIERCUREA SIBIULUI FOREST DISTRICT | B17: Cristina STANCĂ-MOISE, Robert BLAJ | C17: FSAA | D17: Muzeul Olteniei Craiova. Oltenia. Studii şi comunicări. Ştiinţele Naturii | E17: 36 | F17: 1 | G17: ISSN 1454-6914 | H17: http://olteniastudiisicomunicaristiintelenaturii.ro/v36_2.html | I17: http://olteniastudiisicomunicaristiintelenaturii.ro/cont/36_1/III.%20ANIMAL%20BIOLOGY%20III.a.%20INVERTEBRATES%20VARIOUS/9StancaMoise.pdf | J17: ZOOR | K17: 73-77 | L17: 2020 | M17: 200 | N17: 100 | O17: Blaj Robert
A18: THE MAIN CHARACTERISTICS OF AGRICULTURE AND RURAL DEVELOPMENT IN THE CENTRAL REGION OF ROMANIA | B18: Cărătuș Stanciu Mirela | C18: FSAA2 | D18: Scientific Papers-Series Management Economic Engineering in Agriculture and Rural Development | E18: 20 | F18: 4 | G18: 2284-7995 | H18: http://managementjournal.usamv.ro/pdf/vol.20_4/Art17.pdf | J18: 598213900017 | K18: 131-138 | L18: 2020 | M18: 200 | N18: 200 | O18: Caratus Mirela
A19: RESEARCH REGARDING YOUNGER CONSUMERS ATTITUDE, IN RELATION WITH SHEEP MEAT CONSUMPTION | B19: Cărătuș Stanciu Mirela | C19: FSAA2 | D19: Scientific Papers-Series Management Economic Engineering in Agriculture and Rural Development | E19: 20 | F19: 4 | G19: 2284-7995 | H19: http://managementjournal.usamv.ro/pdf/vol.20_4/Art16.pdf | J19: 598213900016 | K19: 125-130 | L19: 2020 | M19: 200 | N19: 200 | O19: Caratus Mirela
A20: TRENDS AND CHANGES IN TOURIST FLOW IN ROMANIA IN THE PERIOD 2009-2018 | B20: Popescu Agatha, Hontuș Adelaida Cristina, Cărătuș Stanciu Mirela | C20: FSAA2 | D20: Scientific Papers-Series Management Economic Engineering in Agriculture and Rural Development | E20: 20 | F20: 1 | G20: 2284-7995 | H20: http://managementjournal.usamv.ro/pdf/vol.20_1/Art56.pdf | J20: 521743100056 | K20: 425-436 | L20: 2020 | M20: 200 | N20: 67 | O20: Caratus Mirela
A21: RESEARCH REGARDING CONSUMERS ATTITUDE, IN RELATION WITH POULTRY MEAT PURCHASE AND CONSUMPTION. CASE STUDY SIBIU, ROMANIA | B21: Cărătuș Stanciu Mirela | C21: FSAA2 | D21: Scientific Papers-Series Management Economic Engineering in Agriculture and Rural Development | E21: 20 | F21: 1 | G21: 2284-7995 | H21: http://managementjournal.usamv.ro/pdf/vol.20_1/Art17.pdf | J21: 521743100017 | K21: 125-130 | L21: 2020 | M21: 200 | N21: 200 | O21: Caratus Mirela
A22: RESEARCH ON GROWTH INDICATORS IN ABERDEEN ANGUS YOUTH CATTLE, ACCORDING TO DIFFERENT INFLUENCING FACTORS | B22: I. T.GOCIMAN, G.E.MĂRGINEAN, S. BĂRĂITĂREANU, Mirela Aurora CĂRĂTUȘ, Livia VIDU | C22: FSAA2 | D22: Scientific Papers. Series D. Animal Science | F22: 2 | G22: 2285-5750 | H22: http://animalsciencejournal.usamv.ro/pdf/2020/issue_1/Art46.pdf | J22: 574608500046 | K22: 319-324 | L22: 2020 | M22: 200 | N22: 40 | O22: Caratus Mirela
A23: STUDY ON A BETTER MANAGEMENT IN A MODERN FARM USING DIFFERENT FUELS FOR TRACTOR ENGINES | B23: Dumitru Mariana | C23: FSAA2 | D23: Lucrări Ştiinţifice Management AGRICOL | E23: Scientific Papers Series Management, Economic Engineering in Agriculture and Rural Development | F23: Vol. 20, Issue 4 | G23: PRINT ISSN 2284-7995, E-ISSN 2285-3952 | H23: http://managementjournal.usamv.ro/pdf/vol.20_4/Art.21.pdf | I23: - | J23: 503074300011 | K23: 161-164 | L23: 2020 | M23: 200 | N23: 200 | O23: Dumitru Mariana
A24: DEVELOPMENT AND ANALYSIS OF FRUIT BEVERAGES WITH ANTIOXIDANT PROPERTIES | B24: Solomatina E.A., Solomatin N.M., Michurinsk State Agr Univ Russia, Sorokopudov V.N., Sorokopudova O.A., Russian State Agr Univ, Hort & Landscape Engn, Russia Myachikova N.I., Frum A., Belogorode State University, Russia, Georgescu C. Lucian Blaga University of Sibiu | C24: FSAA2 | D24: Scientific Study & Research Chemistry & Chemical Engineering, Biotechnology, Food Industry | E24: 21 | F24: 4 | G24: ISSN 1582-540X | H24: http://pubs.ub.ro/?pg=revues&rev=cscc6&num=202004&vol=4&aid=5195 | I24: CSCC6202004V04S01A0010 | J24: WOS:000596118000010 | K24: 555-561 | L24: 2020 | M24: 200 | N24: 100 | O24: Georgescu Cecilia
A25: THE RELATIONSHIP BETWEEN DEMOGRAPHY AND THE DEVELOPMENT OF SMART CITY. CASE STUDY-BUCHAREST. | B25: MARCUTA, L. (USAMV), MARCUTA, A. (USAMV), IAGARU, P.(ULB), IAGARU, R.(ULB), & DIMEN, L. (UAB) | C25: FSAA2 | D25: Scientific Papers: Management, Economic Engineering in Agriculture & Rural Development | E25: 20 | F25: 1 | G25: 2284-7995 / 2285-3952 | H25: http://managementjournal.usamv.ro/index.php/scientific-papers/85-vol-20-issue-1?start=60 | K25: 235-239 | L25: (2020). | M25: 200 | N25: =M25/5 -> 40 | O25: Iagaru Pompilica
A26: THE RELATIONSHIP BETWEEN DEMOGRAPHY AND THE DEVELOPMENT OF SMART CITY. CASE STUDY-BUCHAREST. | B26: MARCUTA, L. (USAMV), MARCUTA, A. (USAMV), IAGARU, P.(ULB), IAGARU, R.(ULB), & DIMEN, L. (UAB) | C26: FSAA2 | D26: Scientific Papers: Management, Economic Engineering in Agriculture & Rural Development | E26: 20 | F26: 1 | G26: 2284-7995 / 2285-3952 | H26: http://managementjournal.usamv.ro/index.php/scientific-papers/85-vol-20-issue-1?start=60 | K26: 235-239 | L26: (2020). | M26: 200 | N26: =M26/5 -> 40 | O26: Iagaru Romulus
A27: Differences Of The Physicochemical Indicators Of Beverages Wild Elderflower (Sambucus Nigra) From Teleajen Valley, Romania, According To The Used Technology | B27: Iancu Maria Lidia | C27: FSAA2 | D27: CARPATHIAN JOURNAL OF FOOD SCIENCE AND TECHNOLOGY | E27: 12 | F27: 3 | G27: Print: ISSN 2066-6845 Online ISSN-L 2344-5459 ISSN-L 2066-6845 | H27: http://chimie-biologie.ubm.ro/carpathian_journal/Vol_12(3)_2020.pdf | I27: https://doi.org/10.34302/crpjfst/2020.12.3.16 | J27: WOS:000579506300016 | K27: 192-200 | L27: 2020 | M27: 200 | N27: 200 | O27: Iancu Maria
A28: Advanced identification and quantification of pesticide residues in vegetables by GC-ToFMS technique | B28: Diana Ionela Stegarus, Roxana Elena Ionete, Ecaterina Lengyel, Marius Gheorghe Miricioiu, | C28: FSAA2 | D28: Rev. Chimie | E28: 71 | F28: 4 | G28: 2668-8212 | H28: https://revistadechimie.ro/pdf/23%20STEGARUS%204%2020.pdf | I28: https://doi.org/10.37358/RC.20.4.8060, | J28: https://www.scopus.com/authid/detail.uri?authorId=14043732700 | K28: 220-229 | L28: 2020 | M28: 200 | N28: 50 | O28: Lengyel Ecaterina
A29: USE OF THE CROP CIRCLE ACS-430 DEVICE FOR IDENTIFYING THE NDVI GREEN INDEX IN A CORN CULTURE IN SIBIU COUNTY, ROMANIA | B29: Moise George | C29: FSAA | D29: Muzeul Olteniei Craiova. Oltenia. Studii şi comunicări. Ştiinţele Naturii | E29: 36 | F29: 2 | G29: ISSN 1454-6914 | H29: http://olteniastudiisicomunicaristiintelenaturii.ro/v36_2.html | I29: http://olteniastudiisicomunicaristiintelenaturii.ro/cont/36_1/III.%20ANIMAL%20BIOLOGY%20III.a.%20INVERTEBRATES%20VARIOUS/9StancaMoise.pdf | J29: ZOOR | K29: 57-62 | L29: 2020 | M29: 200 | N29: 200 | O29: Moise George
A30: MONITORING AND CONTROL OF THE DEFOLIATOR POPULATION Lymantria monacha (L., 1758) WITHIN THE FORESTRY FIELD RASINARI (SIBIU, ROMANIA). | B30: Stanca-Moise Cristina, BRERETON Tom | C30: FSAA | D30: Analele Universitatii din Oradea Fascicula Biologie | E30: 27 | F30: 1 | G30: ISSN:1224-5119 | H30: https://www.bioresearch.ro/2020-1/027-031-AUOFB.27.1.2020-STANCA-MOISE.C.-Monitoring.and.control.pdf | I30: https://apps.webofknowledge.com/full_record.do?product=UA&search_mode=GeneralSearch&qid=1&SID=C6kumWLc1BlEpwHfUok&page=1&doc=1 | J30: ZOOR15611077348 | K30: 27-31 | L30: 2020 | M30: 200 | N30: 200 | O30: Moise Cristina
A31: YIELD POTENTIAL AND STABILITY OF SOME SPRING BARLEY VARIETIES AND LINES | B31: Russu, FM; Porumb, I; Urda, CA ; Filip, E; Stanca-Moise, C; Varadi, A; Vasilescu, L; Petcu, E. | C31: FSAA | D31: SCIENTIFIC PAPERS-SERIES MANAGEMENT ECONOMIC ENGINEERING IN AGRICULTURE AND RURAL DEVELOPMENT | E31: 20 | F31: 1 | G31: ISSN: 2284-7995 | H31: http://managementjournal.usamv.ro/pdf/vol.20_1/Art65.pdf | I31: https://apps.webofknowledge.com/full_record.do?product=UA&search_mode=GeneralSearch&qid=1&SID=C6kumWLc1BlEpwHfUok&page=1&doc=2 | J31: WOS:000521743100065 | K31: 533-538 | L31: 2020 | M31: 200 | N31: 25 | O31: Moise Cristina
A32: Integrated control of damages and diseases within the forest ecosystem “miercurea sibiului” (Sibiu, romania) in the conditions of the year 2019 | B32: Stanca-Moise Cristina, Blaj R. | C32: FSAA | D32: Studia Universitatis Vasile Goldis Arad, Seria Stiintele Vietii | E32: 30 | F32: 3 | G32: ISSN: 15842363 | I32: https://www.scopus.com/record/display.uri?eid=2-s2.0-85097296954&origin=resultslist&sort=plf-f&src=s&st1=Stanc%c4%83+Moise&st2=Cristina&nlo=1&nlr=20&nls=count-f&sid=f45579bd40d782c3d8046c814a427337&sot=anl&sdt=aut&sl=43&s=AU-ID%28%22Stanc%c4%83-Moise%2c+Cristina%22+57191645933%29&relpos=0&citeCnt=0&searchTerm= | J32: Scopus | K32: 149-155 | L32: 2020 | M32: 200 | N32: 100 | O32: Moise Cristina
A33: FOREST AND AGRICULTURAL ECOSYSTEMS PESTS (LEPIDOPTERA), PRESERVED IN THE ENTOMOLOGICAL COLLECTIONS OF THE NATURAL HISTORY MUSEUM IN SIBIU (ROMANIA) | B33: Cristina STANCĂ-MOISE | C33: FSAA | D33: Analele Universitatii din Oradea Fascicula Biologie | E33: 27 | F33: 2 | G33: ISSN: 1224-5119 | H33: https://www.bioresearch.ro/2020-2.html | I33: https://www.bioresearch.ro/2020-2/224-232-AUOFB.27.2.2020-STANCA-MOISE.C-Forest.and.agricultural.pdf | J33: ZOOR | K33: 224-232 | L33: 2020 | M33: 200 | N33: 200 | O33: Moise Cristina
A34: NEW RESEARCH ON THE EVOLUTION OF Lymantria monacha L. (LEPIDOPTERA, LYMANTRIIDAE) IN THE CONDITIONS OF THE YEAR 2019 AND THE CONTROL OF THE PEST POPULATION WITHIN THE MIERCUREA SIBIULUI FOREST RANGE (ROMANIA) | B34: Cristina STANCĂ-MOISE, Robert BLAJ | C34: FSAA | D34: Muzeul Olteniei Craiova. Oltenia. Studii şi comunicări. Ştiinţele Naturii | E34: 36 | F34: 2 | G34: ISSN 1454-6914 | H34: http://olteniastudiisicomunicaristiintelenaturii.ro/v36_2.html | I34: http://olteniastudiisicomunicaristiintelenaturii.ro/cont/36_2/III.%20ANIMAL%20BIOLOGY%20III.a.%20INVERTEBRATES%20VARIOUS/12Moise.pdf | J34: ZOOR | K34: 84-90 | L34: 2020 | M34: 200 | N34: 100 | O34: Moise Cristina
A35: CONTROL OF THE Hylobius abietis L. (COLEOPTERA: CURCULIONIDAE) PEST DURING 2010-2019, WITHIN THE MIERCUREA SIBIULUI FOREST DISTRICT | B35: Cristina STANCĂ-MOISE, Robert BLAJ | C35: FSAA | D35: Muzeul Olteniei Craiova. Oltenia. Studii şi comunicări. Ştiinţele Naturii | E35: 36 | F35: 1 | G35: ISSN 1454-6914 | H35: http://olteniastudiisicomunicaristiintelenaturii.ro/v36_2.html | I35: http://olteniastudiisicomunicaristiintelenaturii.ro/cont/36_1/III.%20ANIMAL%20BIOLOGY%20III.a.%20INVERTEBRATES%20VARIOUS/9StancaMoise.pdf | J35: ZOOR | K35: 73-77 | L35: 2020 | M35: 200 | N35: 100 | O35: Moise Cristina
A36: Immunostimulatory potential of natural compounds and extracts: a review | B36: Stroe A.C., Oancea Simona | C36: FSAA2 | D36: Current Nutrition & Food Science | E36: 16 | F36: 4 | G36: ISSN: 2212-3881 (Online); ISSN: 1573-4013 (Print). | H36: https://www.eurekaselect.com/170390/article | I36: 10.2174/1573401315666190301154200 | J36: WOS:000550991000003 | K36: 444-454 | L36: 2020 | M36: 200 | N36: =M36/2 -> 100 | O36: Oancea Simona
A37: Thermochemical decomposition of sewage sludge - An eco-friendly solution for a sustainable energy future by using wastes | B37: Zaharioiu A., Bucura F., Ionete E.I., Ionete R.E., Ebrasu D., Sandru C., Marin F., Oancea Simona, Niculescu V., Miricioiu M.G., Constantinescu M. | C37: FSAA2 | D37: Rev. Chim. | E37: 71 | F37: 10 | G37: 0034-7752 | H37: https://revistadechimie.ro/pdf/17%20ZAHAROIU%2010%2020.pdf | I37: 10.37358/RC.20.10.8361 | J37: https://www.scopus.com/authid/detail.uri?authorId=6603658504 | K37: 171–181 | L37: 2020 | M37: 200 | N37: 18.18 | O37: Oancea Simona
A38: A historical perspective of food and medicinal uses of antioxidants from natural sources | B38: Tecucianu A.C., Oancea Simona | C38: FSAA2 | D38: Acta Musei Brukenthal | E38: 15 | F38: 3 | G38: 1842-2691 | H38: http://www.brukenthalmuseum.ro/pdf/BAM/BAM%20XV3.pdf | I38: https://www.scopus.com/sources.uri | J38: http://www.brukenthalmuseum.ro/publicatii_en/01.htm | K38: 511-524 | L38: 2020 | M38: 200 | N38: =M38/2 -> 100 | O38: Oancea Simona
A39: An overview on edible mushrooms with health benefits and applications in the food industry | B39: Popa-Vecerdea F.M., Oancea Simona | C39: FSAA2 | D39: Acta Musei Brukenthal | E39: 15 | F39: 3 | G39: 1842-2691 | H39: http://www.brukenthalmuseum.ro/pdf/BAM/BAM%20XV3.pdf | I39: https://www.scopus.com/sources.uri | J39: http://www.brukenthalmuseum.ro/publicatii_en/01.htm | K39: 525-536 | L39: 2020 | M39: 200 | N39: =M39/2 -> 100 | O39: Oancea Simona
A40: Influence of enzymatic and ultrasonic extraction on phenolics content and antioxidant activity of Hibiscus sabdariffa L. flowers | B40: Oancea Simona, Perju M. | C40: FSAA2 | D40: Bulgarian Chemical Communications | E40: 52 | F40: D | G40: 0324-1130 | H40: http://www.bcc.bas.bg/ | I40: https://www.scopus.com/sources.uri | K40: 25-29 | L40: 2020 | M40: 200 | N40: =M40/2 -> 100 | O40: Oancea Simona
A41: INDICATORS FOR INVESTIGATING TRADITIONAL HOME-GARDENS IN ROMANIA - CROPS DIVERSITY IN MOSNA COMMUNE, SIBIU COUNTY | B41: Antofie MM, Sava C (ULBS) | C41: FSAA2 | D41: SCIENTIFIC PAPERS-SERIES MANAGEMENT ECONOMIC ENGINEERING IN AGRICULTURE AND RURAL DEVELOPMENT | E41: 20 | F41: 4 | G41: 2284-7995 | H41: http://managementjournal.usamv.ro/pdf/vol.20_4/Art5.pdf | J41: WOS:000598213900005 | K41: 39-47 | L41: 2020 | M41: 200 | N41: =M41/2 -> 100 | O41: Sava Camelia
A42: INDICATORS FOR INVESTIGATING TRADITIONAL HOME-GARDENS IN ROMANIA-VINEYRADS, FRUIT TREES AND CULTIVATED SHRUBS DIVERSITY IN MOȘNA COMMUNE, SIBIU COUNTY | B42: Antofie MM, Sava C (ULBS) | C42: FSAA2 | D42: SCIENTIFIC PAPERS-SERIES MANAGEMENT ECONOMIC ENGINEERING IN AGRICULTURE AND RURAL DEVELOPMENT | E42: 20 | F42: 4 | G42: 2284-7995 | H42: http://managementjournal.usamv.ro/pdf/vol.20_4/Art6.pdf | J42: WOS:000598213900006 | K42: 49-56 | L42: 200 | M42: 200 | N42: =M42/2 -> 100 | O42: Sava Camelia
A43: How To Use Production Functions Characteristics Of Economic Processes In Agriculture. Physical (Technical) Functions, | B43: Simtion Daniela | C43: FSAA2 | D43: Scientific Papers Series Management, Economic Engineering in Agriculture and Rural Development, | E43: Vol. 20, | F43: Issue 4, | G43: ISSN 2284-7995, 2020, | H43: http://managementjournal.usamv.ro/pdf/vol.20_4/Art56.pdf, | J43: 000598213900056 | K43: 487-490 | L43: 2020 | M43: 200 | N43: 200 | O43: Simtion Daniela
...

Sheet I.4
A2: I.4 - Articol în volum de conferinţă (proceedings) indexat Conference Proceeding Citation Index - CPCI; alte tipuri de publicaţii din WoS
A4: Pentru anul raportării, dacă volumul conferinţei nu a fost încă indexat, pot fi raportate lucrări doar dacă se face dovada indexării volumelor anterioare ale conferinţei (cel puțin una din ultimele două ediții ale conferinței trebuie să fie vizibile WoS).
A5: La acest indicator se punctează şi articolele în reviste indexate WoS sau în reviste din baza de date Master Journal List care nu se încadrează in document type ca „article” sau „review”.
A6: Articolul trebuie să conţină menţiunea afilierii la ULBS a declarantului.
A7: * Punctaje de referință: • Articol = 100 de puncte Punctajul se împarte la numărul de autori cu afiliere la instituţiile de învăţământ şi cercetare din România, inclusiv la doctoranzi / studenţi. Punctajul NU se împarte cu autorii din străinătate sau cu autorii din mediul de afaceri (pentru acești autori se menţionează în paranteză instituţia de proveniență).
A9: Titlul articolului | B9: Tipul articolulului (articol, abstract, book review, letter, etc.) | C9: Numele și prenumele autorilor (afilierea) | D9: Cod Departament | E9: Titlul conferinței / Titlul volumului / Titlul revistei | F9: ISSN / ISBN | G9: Paginile articolului (de la … pana la …) | H9: DOI articol (Digital object identifier) | I9: WOS Accession Number | J9: Site www al conferinței | K9: Anul publicării | L9: Punctaj de referință* | M9: Punctaj individual | N9: Numele și prenumele Declarant
A10: PUBLIC OPINION AND PUBLIC FOREST MANAGEMENT POLICIES IN THE CONTEXT OF COVID-19 | B10: Articol | C10: Bratu I.A. (Univ."Lucian Blaga"), Dincă L. (INCDS) | D10: FSAA2 | E10: Review of Management and Economic Engineering | J10: http://conference.rmee.org/ | K10: 2020 | L10: 100 | M10: 50 | N10: Bratu Alexandru
A12: Overcoming the barriers of consignment stock policy implementation in a manufacturing company | B12: articol | C12: M. Faur, A. Sipos, C. Bungau and C.I. Gherghea | D12: FSAA2 | E12: Annual Session of Scientific Papers - IMT Oradea 2020, IOP Conf. Series: Materials Science and Engineering | F12: - | G12: - | H12: 10.1088/1757-899X/898/1/012026 | I12: - | J12: https://imt.uoradea.ro/conference/Proceedings_2020.pdf, https://iopscience.iop.org/issue/1757-899X/898/1 | K12: 2020 | L12: 100 | M12: =100/4 -> 25 | N12: Sipos Anca
A13: Balneary Tourism, a Chance for Sustainable Regional Development | B13: ULBS | C13: Nicula V. (ULBS), Spânu Simona (ULBS) | D13: FSAA2 | E13: Organizations and Performance in a Complex World | F13: ISBN 978-3-030-50676-6 | G13: 205-216 | H13: https://www.springer.com/gp/book/9783030506759 | J13: www.iecs | K13: 2020 | L13: 100 | M13: 50 | N13: Spanu Simona
A60: TOTAL | M60: =SUM(M10:M59) -> 125
A62: Informațiile incomplete / incorecte vor conduce la neluarea în calcul a indicatorului respectiv

Sheet I.5
A2: I.5 - Publicaţii BDI şi publicaţii ERIH PLUS
A4: Se raportează articolele şi recenziile publicate in reviste indexate BDI – baze de date internaţionale, inclusiv revistele indexate ERIH PLUS (https://dbh.nsd.uib.no/publiseringskanaler/erihplus/).
A5: Se raportează doar articolele şi recenziile, nu şi rezumatele.
A6: Nu se raportează articole de tip Conference Paper.
A7: * Punctaje de referință: • Articol = 70 de puncte • Recenzie = 25 de puncte Punctajul se împarte la numărul de autori cu afiliere la instituţiile de învăţământ şi cercetare din România, inclusiv la doctoranzi / studenţi. Punctajul NU se împarte cu autorii din străinătate sau cu autorii din mediul de afaceri (pentru acești autori se menţionează în paranteză instituţia de proveniență).
A9: Titlul articolului | B9: Numele și prenumele autorilor (afilierea) | C9: Cod Departament | D9: Titlul revistei | E9: Volumul | F9: Numarul | G9: ISSN / ISBN | H9: Anul publicării | I9: Paginile articolului (de la … până la …) | J9: Baza de date în care este indexată revista | K9: Link către articol | L9: Punctaj de referință* | M9: Punctaj individual | N9: Numele și prenumele Declarant
A10: Assessment of the Distribution and Characteristics of the Oldest Forest Stand from the Romanian's Western Plain. | B10: Dincă L. (INCDS), Bratu I.A. (Univ."Lucian Blaga") | C10: FSAA2 | D10: Bulletin of the University of Agricultural Sciences & Veterinary Medicine Cluj-Napoca. Animal Science & Biotechnologies | E10: 77 | F10: 2 | G10: 1843-5246 | H10: 2020 | I10: 9-14 | J10: EBSCO, CABI | K10: http://journals.usamvcluj.ro/index.php/agriculture/article/view/13917 | L10: 70 | M10: 35 | N10: Bratu Alexandru
A11: Contributions to the Characterization of Forest Soils from Calarasi County | B11: Dincă L. (INCDS), Bratu I.A. (Univ."Lucian Blaga") | C11: FSAA2 | D11: JOURNAL of Horticulture, Forestry and Biotechnology | E11: 24 | F11: 1 | G11: 2066-1797 | H11: 2020 | I11: 46-49 | J11: IndexCopernicus, CABI | K11: https://drive.google.com/file/d/11xMACfg7Qp4rueZkbcwL70dtmC0hQIwR/view?usp=sharing | L11: 70 | M11: 35 | N11: Bratu Alexandru
A12: Study of awareness of food labeling among consumers in North-West Russia | B12: Mark Shamtsyan, Boris Kolesnikov, Mikhail Pushkarev - SIT-Russia, Liviu Gaceu, Oana Bianca Oprea Universitatea Transilvania din Brasov, Iulia Iatco rep Moldova, Dumitru Mnerie, Gabriela Mnerie Timisoara, Ovidiu Tita, Mihaela Tita, Cecilia Georgescu, Monica Mironescu, -ULBS, Stefan Stefanov and Stanka Damianova, Bulgaria | C12: FSAA2 | D12: E3S Web of Conf. International Scientific Conference on Biotechnology and Food Technology (BFT-2020) | E12: 215 | G12: eISSN: 2267-1242 | H12: 2020 | I12: 1-8 | J12: - Google Scholar - EDP Sciences database | K12: 10.1051/e3sconf/202021501002 | L12: 70 | M12: 8.75 | N12: Georgescu Cecilia
A13: STRATEGIC MANAGEMENT OF SUSTAINABLE VALORIZATION OF ENDOGENIC RESOURCES IN GUȘOENI COMMUNE, VÂLCEA COUNTY. | B13: Nicolae, Concioiu (UCV); Romulus, Iagăru (ULB) | C13: FSAA2 | D13: Annals of the University of Craiova, Economic Sciences Series | E13: 20 | F13: 2 | G13: 1223-365X | H13: 2020 | I13: 63-70 | J13: RePEC, EBSCO, DOAJ and CEEOL | K13: http://feaa.ucv.ro/annals/v1_2020/006.pdf | L13: 70 | M13: =L13/2 -> 35 | N13: Iagaru Romulus
A14: Identification and quantification of total polyphenols in musts and aromatic and semiaromatic wines | B14: Ioana Rebenciuc, Ecaterina Lengyel, Diana Ionela Stegăruș, Petru Alexe, Anamaria Călugăr | C14: FSAA2 | D14: AAB BIOFLUX | E14: 12 | F14: 3 | G14: 2067-6352 | H14: 2020 | I14: 106-111 | J14: CABI, PROQUEST | K14: http://www.aab.bioflux.com.ro/docs/2020.106-111.pdf | L14: 70 | M14: 14 | N14: Lengyel Ecaterina
A15: Study of awareness of food labeling among consumers in North-West Russia | B15: Mark Shamtsyan, Boris Kolesnikov, Mikhail Pushkarev - SIT-Russia, Liviu Gaceu, Oana Bianca Oprea Universitatea Transilvania din Brasov, Iulia Iatco rep Moldova, Dumitru Mnerie, Gabriela Mnerie Timisoara, Ovidiu Tita, Mihaela Tita, Cecilia Georgescu, Monica Mironescu, -ULBS, Stefan Stefanov and Stanka Damianova, Bulgaria | C15: FSSA2 | D15: E3S Web of Conf. Volume 215, 2020 International Scientific Conference on Biotechnology and Food Technology (BFT-2020) | E15: 215 | G15: eISSN: 2267-1242 | H15: 2020 | K15: 10.1051/e3sconf/202021501002 | L15: 70 | M15: 8.75 | N15: Mironescu Monica
A16: MANAGEMENT OF URINARY TRACT INFECTIONS | B16: Magda PANAITESCU , Daniela Maria ȘANDRU Universidad ”Latina” de Panama, Rep. de Panama, “Lucian Blaga” University of Sibiu, Romania, | C16: FSAA2 | D16: Management of Sustainable Development Sibiu, Romania, | E16: 12 | F16: 1 | G16: 2247 – 0220 | H16: Iunie 2020 | I16: 33-35 | J16: BDI | K16: https://msdjournal.org/wp-content/uploads/vol12issue1-5.pdf | L16: 70 | M16: 70 | N16: Sandru Daniela
A17: THE ANTIBACTERIAL POTENTIAL OF ESSENTIAL OILS ON PROPIONIBACTERIUM GRANULOSUM STRAINS | B17: Șandru, Daniela Maria and Panaitescu, Magda “Lucian Blaga” University of Sibiu, Romania, Universidad ”Latina” de Panama, Rep. de Panama, | C17: FSAA2 | D17: Management of Sustainable Development Sibiu, Romania, | E17: 12 | F17: 2 | G17: 2247 – 0220 | H17: Decembrie 2020 | I17: 21-24 | J17: BDI | K17: https://msdjournal.org/wp-content/uploads/vol12issue2-3.pdf | L17: 70 | M17: 70 | N17: Sandru Daniela
A18: Research on the evolution of sensory and physico-chemical characteristics of butter with the addition of mint and peppermint | B18: Mihaela Adriana Tiţa (ULBS), Butoi Laurenţiu(Liceul Tehnologic de Industrie Alimentara Sibiu) | C18: FSAA2 | D18: Management of Sustainable Development | E18: Volume 12 | F18: No. 1 | G18: 2247-0220 | H18: 2020 | I18: 19-20 | J18: EBSCO, Google Scholar, Index Copernicus , J-Gate, ResearchGate, | K18: http://rosita.ro/jeat/archive/1_2019.pdf | L18: 70 | M18: 70 | N18: Tita Mihaela
A19: MARKETING ASPECTS OF YOGHURT ENHANCEDWITH TAPIOCA | B19: 4. Moga, Valentina Mădălina (High Schoolof Food Industry), Tița, Mihaela Adriana (ULBS) | C19: FSAA2 | D19: Management of Sustainable Development | E19: Vol.12 | F19: No.2 | G19: 2247 – 0220 | H19: 2020 | I19: 12-20 | J19: EBSCO, Google Scholar, Index Copernicus , J-Gate, ResearchGate, | L19: 70 | M19: 70 | N19: Tita Mihaela
A20: Studies on the implementation of an innovative "fatty" dairy product with bioactive components | B20: M. Păunoiu (SC.Boromir SA), M. Tiţa (ULBS), | C20: FSAA2 | D20: Journal of EcoAgriTourism | E20: Vol. 16 | F20: No.2 | G20: 1844-8577 | H20: 2020 | I20: 56-63 | J20: CNCSIS cod 910 , CAB Abstracts , Global Health, Jeat. | K20: 1. http://rosita.ro/jeat/archive/2_2020.pdf | L20: 70 | M20: 70 | N20: Tita Mihaela
A21: M. Tiţa, O.Popa | B21: M. Tiţa (ULBS), O.Popa (ULBS) | C21: FSAA2 | D21: Journal of EcoAgriTourism | E21: Vol. 16 | F21: No.2 | G21: 1844-8577 | H21: 2020 | I21: 64-71 | J21: CNCSIS cod 910 , CAB Abstracts , Global Health, Jeat. | K21: 1. http://rosita.ro/jeat/archive/2_2020.pdf | L21: 70 | M21: 35 | N21: Tita Mihaela
A22: Biochemical approaches for goat milk yogurt production | B22: Cristina POPOVICI(TechnicalUniversityofMoldova, Chisinau), Mihaela Adriana TIȚA (ULBS), Anatolii CARTASEV (ScientificandPracticalInstituteofHorticultureandFoodTechnology, Chisinau), Vladislav RESITCA (ScientificandPracticalInstituteofHorticultureandFoodTechnology, Chisinau), Nina BOGDAN (ScientificandPracticalInstituteofHorticultureandFoodTechnology, Chisinau), Olga MIGALATIEV(ScientificandPracticalInstituteofHorticultureandFoodTechnology, Chisinau) | C22: FSAA2 | D22: Scientific Bulletin. Series F. Biotechnologies | E22: Vol. XXIV | F22: No.2 | G22: ISSN 2285-1364 | H22: 2020 | I22: 49-50 | J22: INDEX COPERNICUS, CABI, DOAJ, GOOGLE SCHOLAR, SCIPIO | K22: http://biotechnologyjournal.usamv.ro/pdf/2020/issue_2/Art6.pdf | L22: 70 | M22: 70 | N22: Tita Mihaela
A23: Ensuring sustainability in dairy processing for a circular economy | B23: Tita Ovidiu | C23: FSAA2 | D23: Journal of EcoAgriTourism | E23: 16 | F23: 2 | G23: ISNB:1844-8577 | H23: 2020 | I23: 72-76 | J23: CAB Abstracts, Global Health | K23: http://rosita.ro/jeat/archive/2_2020.pdf | L23: 70 | M23: 70 | N23: Tita Ovidiu
A24: Study of the chemical composition and antioxidant activity of some varieties of young red wines from different vineyards in southern Romania | B24: Onache Petronela Anca – INCDBH Stefanesti, Arges; Sumedrea Dorin Ioan - INCDBH Stefanesti, Arges; Tita Ovidiu – Universitatea “Lucian Blaga” Sibiu; Nicolescu Eugen – VITIS SA Babadag | C24: FSAA2 | D24: Scientific Papers. Series B, Horticulture. | E24: LXIV | F24: 1 | G24: Print ISSN 2285-5653, CD-ROM ISSN 2285-5661, Online ISSN 2286-1580, ISSN-L 2285-5653 | H24: 2020 | I24: 307-315 | J24: Web of Science Core Collection (Emerging Sources Citation Index - THOMSON REUTERS), CABI, INDEX COPERNICUS, CNCSIS B+ , Ulrich's Periodicals Directory, Google Scholar, PBN (Polish Scholarly Bibliography), Scipio, Scientific Indexing Service, OCLC (WorldCat), Research bible | K24: http://horticulturejournal.usamv.ro/pdf/2020/issue_1/Art46.pdf | L24: 70 | M24: 17.5 | N24: Tita Ovidiu
A61: TOTAL | M61: =SUM(M10:M60) -> 679
A63: Informațiile incomplete / incorecte vor conduce la neluarea în calcul a indicatorului respectiv

Sheet I.6
A2: I6 - Cărţi ştiinţifice de autor şi capitole publicate la edituri internaţionale de prestigiu și edituri internaționale (sau traduse pentru domeniul Filologie şi Teologie, sau traducere de text dramatic și carte de autor pentru domeniul Artele spectacolului).
A4: Se va verifica existenţa volumului fizic / CD electronic prin depunerea unui exemplar al cărţii la departament, respectiv prin existenţa în mediul on-line.
A5: Lista editurilor internationale de prestigiu se regaseste pe site-ul Serviciului CD: http://cercetare.ulbsibiu.ro/siepas.html. O editură este considerată internaţională dacă ISBN-ul este din străinătate şi cartea este publicată într-o limbă de circulaţie internaţională. Editurile din Republica Moldova sunt considerate edituri naţionale, indiferent de limba în care sunt publicate cărţile.
A6: În această categorie intră automat şi cărţile / capitolele de cărţi indexate în TR şi respectiv Scopus. Nu se acceptă ȋn această categorie volumele de conferință (Proceedings).
A7: Plafoane maxime anuale, pentru publicarea în edituri internaţionale de prestigiu: • 1500 puncte / declarant, indiferent de numărul de cărţi declarate Plafoane maxime anual, cerinţe cumulative pentru publicarea în edituri internaţionale: • 1500 puncte / declarant, indiferent de numărul de cărţi declarate • 1500 puncte / carte, indiferent de numărul de declaranţi
A8: * Punctaje de referință: • 10 puncte / pagină, pentru carte nouă publicată în edituri internaţionale de prestigiu (lista este disponibilă pe site-ul CD) • 3,5 puncte / pagină, pentru cărţi noi publicate la alte edituri internaţionale • 2,5 puncte per pagina re-editări • 1,5 puncte per pagină traducere, pentru domeniul Filologie şi Teologie • 0,5 puncte / pagină, pentru traducere de text dramatic și carte științifică de autor pentru domeniul Artele spectacolului
A9: Punctajul se alocă numai pentru capitolele care precizează contribuţia declarantului, împărţindu-se la numărul co-autorilor din ţară. Pentru co-autorii din străinătate se menţionează în paranteză instituţia. În cazul în care contribuţia individuală nu poate fi identificată, se împarte punctajul total rezultat pentru carte / capitol, la numărul autorilor din ţară. Pentru autorii din străinătate se menţionează în paranteză instituţia
A11: Titlul cărții | B11: Numele și prenumele autorilor | C11: Cod Departament | D11: Editura (se precizează în paranteză dacă este vorba de editură de prestigiu) | E11: ISBN-ul cărții | F11: Anul publicării | G11: Luna publicării | H11: Nr. pag. | I11: Punctaj de referință* | J11: Punctaj individual | K11: Numele și prenumele Declarant
A12: GENETICALLY MODIFIED AND IRRADIATED FOOD: CONTROVERSIAL ISSUES: FACTS VERSUS PERCEPTIONS | B12: Mathe E. (HU, Debretin Univ.), Antofie MM | C12: FSAA2 | D12: ACADEMIC PRESS LTD-ELSEVIER SCIENCE LTD, 125 LONDON WALL, LONDON EC2Y 5AS, ENGLAND | E12: 978-0-12-817241-4; 978-0-12-817240-7 | F12: 2020 | G12: ian. | H12: 24 | I12: 240 | J12: 240 | K12: Antofie Mihaela
A13: Capitol "Improving the Training Methods for Designers of Flexible Production Cells in Factories of the Future" in: Boosting Collaborative Networks 4.0 | B13: Mironescu I., Crăciunean DC., Florea A., Bondrea I. | C13: FSAA2 | D13: SpringerLink | E13: 978-3-030-62412-5 | F13: 2020 | G13: Nov | H13: 15 | I13: =H13*10 -> 150 | J13: =I13/4 -> 37.5 | K13: Mironescu Ion
A14: IMPROVING THE CONSISTENCY OF COW'S MILK YOGURT By adding tapioca powder | B14: Moga Valentina Madalina, Mihaela-Adriana Tita, | C14: FSAA2 | D14: https://www.lap-publishing.com/catalog/details/store/tr/book/978-620-3-19796-9/improving-the-consistency-of-cow-s-milk-yogurt?search=tita%20miahela | E14: ISBN 978-620-3-19796-9 | F14: 2020 | G14: decembrie | H14: 216 | I14: 756 | J14: 378 | K14: Tita Mihaela
A15: Destination Management and Marketing: Breakthroughs in Research and Practice, Cap. 68 - Ways to Promoting Rural, Cultural and Gastronomical Tourism in Mărginimea Sibiului (pages 1206-1214) | B15: Nicula V., Spânu Simona | C15: FSAA2 | D15: IGI-Global https://www.igi-global.com/chapter/ways-to-promoting-rural-cultural-and-gastronomical-tourism-in-mrginimea-sibiului/251105 | E15: DOI: 10.4018/978-1-7998-2469-5.ch068 | F15: 2020 | H15: 9 | I15: 31.5 | J15: 15.75 | K15: Spanu Simona
A62: TOTAL | J62: =SUM(J12:J61) -> 671.25
A64: Informațiile incomplete / incorecte vor conduce la neluarea în calcul a indicatorului respectiv

Sheet I.7
